2025-06-19 12:16:37,613 - INFO - Chargement des données depuis /Users/thiarakante/Documents/Databeez/prediction_parcours/src/data/shift_data.xlsx
2025-06-19 12:16:37,738 - INFO - Données chargées : 402 lignes, 13 colonnes
2025-06-19 12:16:37,738 - INFO - Colonnes disponibles : ['numero etudiant', 'Sciences_fondamentales', 'Biologie_Biophysique', 'Electronique_Automatique', 'Mécanique', 'Communication', 'Semestre', 'Maintenance_Systèmes', 'Gestion_Risques_HQSE', 'Informatique', 'Biomédical', 'Moyenne_generale', 'decision_semestrielle']
2025-06-19 12:16:37,739 - INFO - Valeurs cibles uniques : ['valide' 'Non valide']
2025-06-19 12:16:37,739 - INFO - Début de l'entraînement des modèles...
2025-06-19 12:16:37,739 - ERROR - Erreur lors de l'exécution : "['age', 'Moyenne generale', 'lieu_naissance'] not found in axis"
Traceback (most recent call last):
  File "/Users/thiarakante/Documents/Databeez/prediction_parcours copie/main.py", line 41, in main
    pipeline, model, label_encoder, model_name = train_and_compare_models(df)
  File "/Users/thiarakante/Documents/Databeez/prediction_parcours copie/src/components/modelling.py", line 24, in train_and_compare_models
    X = df.drop(columns=[target_col] + excluded_columns)  # Exclure directement les colonnes
  File "/Users/thiarakante/Documents/Databeez/prediction_parcours copie/.venv/lib/python3.10/site-packages/pandas/core/frame.py", line 5581, in drop
    return super().drop(
  File "/Users/thiarakante/Documents/Databeez/prediction_parcours copie/.venv/lib/python3.10/site-packages/pandas/core/generic.py", line 4788, in drop
    obj = obj._drop_axis(labels, axis, level=level, errors=errors)
  File "/Users/thiarakante/Documents/Databeez/prediction_parcours copie/.venv/lib/python3.10/site-packages/pandas/core/generic.py", line 4830, in _drop_axis
    new_axis = axis.drop(labels, errors=errors)
  File "/Users/thiarakante/Documents/Databeez/prediction_parcours copie/.venv/lib/python3.10/site-packages/pandas/core/indexes/base.py", line 7070, in drop
    raise KeyError(f"{labels[mask].tolist()} not found in axis")
KeyError: "['age', 'Moyenne generale', 'lieu_naissance'] not found in axis"
2025-06-19 12:26:07,583 - INFO - Chargement des données depuis /Users/thiarakante/Documents/Databeez/prediction_parcours/src/data/shift_data.xlsx
2025-06-19 12:26:07,693 - INFO - Données chargées : 402 lignes, 13 colonnes
2025-06-19 12:26:07,694 - INFO - Colonnes disponibles : ['numero etudiant', 'Sciences_fondamentales', 'Biologie_Biophysique', 'Electronique_Automatique', 'Mécanique', 'Communication', 'Semestre', 'Maintenance_Systèmes', 'Gestion_Risques_HQSE', 'Informatique', 'Biomédical', 'Moyenne_generale', 'decision_semestrielle']
2025-06-19 12:26:07,694 - INFO - Valeurs cibles uniques : ['valide' 'Non valide']
2025-06-19 12:26:07,694 - INFO - Début de l'entraînement des modèles...
2025-06-19 12:26:09,879 - INFO - Entraînement terminé en 2.18 secondes
2025-06-19 12:26:09,879 - INFO - Meilleur modèle sélectionné : DecisionTree
2025-06-19 12:26:09,879 - INFO - Sauvegarde des artefacts...
2025-06-19 12:26:09,883 - INFO - Analyse des features importantes...
2025-06-19 12:26:09,887 - INFO - Importances des features sauvegardées dans /Users/thiarakante/Documents/Databeez/prediction_parcours/src/components/artifacts/feature_importances.csv
2025-06-19 12:26:09,887 - INFO - Pipeline exécuté avec succès !
2025-06-19 12:35:04,245 - INFO - Chargement des données depuis /Users/thiarakante/Documents/Databeez/prediction_parcours/src/data/shift_data.xlsx
2025-06-19 12:35:04,424 - INFO - Données chargées : 402 lignes, 13 colonnes
2025-06-19 12:35:04,424 - INFO - Colonnes disponibles : ['numero etudiant', 'Sciences_fondamentales', 'Biologie_Biophysique', 'Electronique_Automatique', 'Mécanique', 'Communication', 'Semestre', 'Maintenance_Systèmes', 'Gestion_Risques_HQSE', 'Informatique', 'Biomédical', 'Moyenne_generale', 'decision_semestrielle']
2025-06-19 12:35:04,425 - INFO - Valeurs cibles uniques : ['valide' 'Non valide']
2025-06-19 12:35:04,425 - INFO - Début de l'entraînement des modèles...
2025-06-19 12:35:04,548 - ERROR - Erreur lors de l'exécution : RandomizedSearchCV.__init__() got an unexpected keyword argument 'n_estimators'
Traceback (most recent call last):
  File "/Users/thiarakante/Documents/Databeez/prediction_parcours copie/main.py", line 41, in main
    pipeline, model, label_encoder, model_name = train_and_compare_models(df)
  File "/Users/thiarakante/Documents/Databeez/prediction_parcours copie/src/components/modelling.py", line 97, in train_and_compare_models
    search = RandomizedSearchCV(
TypeError: RandomizedSearchCV.__init__() got an unexpected keyword argument 'n_estimators'
2025-06-19 12:35:34,008 - INFO - Chargement des données depuis /Users/thiarakante/Documents/Databeez/prediction_parcours/src/data/shift_data.xlsx
2025-06-19 12:35:34,120 - INFO - Données chargées : 402 lignes, 13 colonnes
2025-06-19 12:35:34,120 - INFO - Colonnes disponibles : ['numero etudiant', 'Sciences_fondamentales', 'Biologie_Biophysique', 'Electronique_Automatique', 'Mécanique', 'Communication', 'Semestre', 'Maintenance_Systèmes', 'Gestion_Risques_HQSE', 'Informatique', 'Biomédical', 'Moyenne_generale', 'decision_semestrielle']
2025-06-19 12:35:34,121 - INFO - Valeurs cibles uniques : ['valide' 'Non valide']
2025-06-19 12:35:34,121 - INFO - Début de l'entraînement des modèles...
2025-06-19 12:35:35,770 - INFO - Entraînement terminé en 1.65 secondes
2025-06-19 12:35:35,770 - INFO - Meilleur modèle sélectionné : DecisionTree
2025-06-19 12:35:35,771 - INFO - Sauvegarde des artefacts...
2025-06-19 12:35:35,778 - INFO - Analyse des features importantes...
2025-06-19 12:35:35,783 - INFO - Importances des features sauvegardées dans /Users/thiarakante/Documents/Databeez/prediction_parcours/src/components/artifacts/feature_importances.csv
2025-06-19 12:35:35,783 - INFO - Pipeline exécuté avec succès !
2025-06-19 12:48:03,863 - INFO - Chargement des données depuis /Users/thiarakante/Documents/Databeez/prediction_parcours/src/data/shift_data.xlsx
2025-06-19 12:48:04,002 - INFO - Données chargées : 402 lignes, 13 colonnes
2025-06-19 12:48:04,002 - INFO - Colonnes disponibles : ['numero etudiant', 'Sciences_fondamentales', 'Biologie_Biophysique', 'Electronique_Automatique', 'Mécanique', 'Communication', 'Semestre', 'Maintenance_Systèmes', 'Gestion_Risques_HQSE', 'Informatique', 'Biomédical', 'Moyenne_generale', 'decision_semestrielle']
2025-06-19 12:48:04,003 - INFO - Valeurs cibles uniques : ['valide' 'Non valide']
2025-06-19 12:48:04,003 - INFO - Début de l'entraînement des modèles...
2025-06-19 12:48:05,855 - INFO - Entraînement terminé en 1.85 secondes
2025-06-19 12:48:05,855 - INFO - Meilleur modèle sélectionné : DecisionTree
2025-06-19 12:48:05,855 - INFO - Sauvegarde des artefacts...
2025-06-19 12:48:05,857 - INFO - Analyse des features importantes...
2025-06-19 12:48:05,867 - INFO - Importances des features sauvegardées dans /Users/thiarakante/Documents/Databeez/prediction_parcours/src/components/artifacts/feature_importances.csv
2025-06-19 12:48:05,867 - INFO - Pipeline exécuté avec succès !
2025-06-19 12:48:24,009 - INFO - Chargement des données depuis /Users/thiarakante/Documents/Databeez/prediction_parcours/src/data/shift_data.xlsx
2025-06-19 12:48:24,117 - INFO - Données chargées : 402 lignes, 13 colonnes
2025-06-19 12:48:24,117 - INFO - Colonnes disponibles : ['numero etudiant', 'Sciences_fondamentales', 'Biologie_Biophysique', 'Electronique_Automatique', 'Mécanique', 'Communication', 'Semestre', 'Maintenance_Systèmes', 'Gestion_Risques_HQSE', 'Informatique', 'Biomédical', 'Moyenne_generale', 'decision_semestrielle']
2025-06-19 12:48:24,117 - INFO - Valeurs cibles uniques : ['valide' 'Non valide']
2025-06-19 12:48:24,117 - INFO - Début de l'entraînement des modèles...
2025-06-19 12:48:25,625 - INFO - Entraînement terminé en 1.51 secondes
2025-06-19 12:48:25,625 - INFO - Meilleur modèle sélectionné : DecisionTree
2025-06-19 12:48:25,625 - INFO - Sauvegarde des artefacts...
2025-06-19 12:48:25,628 - INFO - Analyse des features importantes...
2025-06-19 12:48:25,634 - INFO - Importances des features sauvegardées dans /Users/thiarakante/Documents/Databeez/prediction_parcours/src/components/artifacts/feature_importances.csv
2025-06-19 12:48:25,634 - INFO - Pipeline exécuté avec succès !
2025-06-19 12:52:02,309 - INFO - Chargement des données depuis /Users/thiarakante/Documents/Databeez/prediction_parcours/src/data/shift_data.xlsx
2025-06-19 12:52:02,423 - INFO - Données chargées : 402 lignes, 13 colonnes
2025-06-19 12:52:02,423 - INFO - Colonnes disponibles : ['numero etudiant', 'Sciences_fondamentales', 'Biologie_Biophysique', 'Electronique_Automatique', 'Mécanique', 'Communication', 'Semestre', 'Maintenance_Systèmes', 'Gestion_Risques_HQSE', 'Informatique', 'Biomédical', 'Moyenne_generale', 'decision_semestrielle']
2025-06-19 12:52:02,423 - INFO - Valeurs cibles uniques : ['valide' 'Non valide']
2025-06-19 12:52:02,423 - INFO - Début de l'entraînement des modèles...
2025-06-19 12:52:02,426 - ERROR - Erreur lors de l'exécution : name 'cross_val_score' is not defined
Traceback (most recent call last):
  File "/Users/thiarakante/Documents/Databeez/prediction_parcours copie/main.py", line 41, in main
    pipeline, model, label_encoder, model_name = train_and_compare_models(df)
  File "/Users/thiarakante/Documents/Databeez/prediction_parcours copie/src/components/modelling.py", line 73, in train_and_compare_models
    cv_scores = cross_val_score(pipe, X, y_encoded, cv=4, scoring='accuracy')
NameError: name 'cross_val_score' is not defined
2025-06-19 12:52:25,421 - INFO - Chargement des données depuis /Users/thiarakante/Documents/Databeez/prediction_parcours/src/data/shift_data.xlsx
2025-06-19 12:52:25,591 - INFO - Données chargées : 402 lignes, 13 colonnes
2025-06-19 12:52:25,591 - INFO - Colonnes disponibles : ['numero etudiant', 'Sciences_fondamentales', 'Biologie_Biophysique', 'Electronique_Automatique', 'Mécanique', 'Communication', 'Semestre', 'Maintenance_Systèmes', 'Gestion_Risques_HQSE', 'Informatique', 'Biomédical', 'Moyenne_generale', 'decision_semestrielle']
2025-06-19 12:52:25,592 - INFO - Valeurs cibles uniques : ['valide' 'Non valide']
2025-06-19 12:52:25,592 - INFO - Début de l'entraînement des modèles...
2025-06-19 12:52:25,608 - ERROR - Erreur lors de l'exécution : 
All the 4 fits failed.
It is very likely that your model is misconfigured.
You can try to debug the error by setting error_score='raise'.

Below are more details about the failures:
--------------------------------------------------------------------------------
1 fits failed with the following error:
Traceback (most recent call last):
  File "/Users/thiarakante/Documents/Databeez/prediction_parcours copie/.venv/lib/python3.10/site-packages/sklearn/model_selection/_validation.py", line 866, in _fit_and_score
    estimator.fit(X_train, y_train, **fit_params)
  File "/Users/thiarakante/Documents/Databeez/prediction_parcours copie/.venv/lib/python3.10/site-packages/sklearn/base.py", line 1389, in wrapper
    return fit_method(estimator, *args, **kwargs)
  File "/Users/thiarakante/Documents/Databeez/prediction_parcours copie/.venv/lib/python3.10/site-packages/sklearn/pipeline.py", line 662, in fit
    self._final_estimator.fit(Xt, y, **last_step_params["fit"])
  File "/Users/thiarakante/Documents/Databeez/prediction_parcours copie/.venv/lib/python3.10/site-packages/sklearn/base.py", line 1389, in wrapper
    return fit_method(estimator, *args, **kwargs)
  File "/Users/thiarakante/Documents/Databeez/prediction_parcours copie/.venv/lib/python3.10/site-packages/sklearn/linear_model/_logistic.py", line 1222, in fit
    X, y = validate_data(
  File "/Users/thiarakante/Documents/Databeez/prediction_parcours copie/.venv/lib/python3.10/site-packages/sklearn/utils/validation.py", line 2961, in validate_data
    X, y = check_X_y(X, y, **check_params)
  File "/Users/thiarakante/Documents/Databeez/prediction_parcours copie/.venv/lib/python3.10/site-packages/sklearn/utils/validation.py", line 1370, in check_X_y
    X = check_array(
  File "/Users/thiarakante/Documents/Databeez/prediction_parcours copie/.venv/lib/python3.10/site-packages/sklearn/utils/validation.py", line 1055, in check_array
    array = _asarray_with_order(array, order=order, dtype=dtype, xp=xp)
  File "/Users/thiarakante/Documents/Databeez/prediction_parcours copie/.venv/lib/python3.10/site-packages/sklearn/utils/_array_api.py", line 839, in _asarray_with_order
    array = numpy.asarray(array, order=order, dtype=dtype)
ValueError: could not convert string to float: 'S4'

--------------------------------------------------------------------------------
3 fits failed with the following error:
Traceback (most recent call last):
  File "/Users/thiarakante/Documents/Databeez/prediction_parcours copie/.venv/lib/python3.10/site-packages/sklearn/model_selection/_validation.py", line 866, in _fit_and_score
    estimator.fit(X_train, y_train, **fit_params)
  File "/Users/thiarakante/Documents/Databeez/prediction_parcours copie/.venv/lib/python3.10/site-packages/sklearn/base.py", line 1389, in wrapper
    return fit_method(estimator, *args, **kwargs)
  File "/Users/thiarakante/Documents/Databeez/prediction_parcours copie/.venv/lib/python3.10/site-packages/sklearn/pipeline.py", line 662, in fit
    self._final_estimator.fit(Xt, y, **last_step_params["fit"])
  File "/Users/thiarakante/Documents/Databeez/prediction_parcours copie/.venv/lib/python3.10/site-packages/sklearn/base.py", line 1389, in wrapper
    return fit_method(estimator, *args, **kwargs)
  File "/Users/thiarakante/Documents/Databeez/prediction_parcours copie/.venv/lib/python3.10/site-packages/sklearn/linear_model/_logistic.py", line 1222, in fit
    X, y = validate_data(
  File "/Users/thiarakante/Documents/Databeez/prediction_parcours copie/.venv/lib/python3.10/site-packages/sklearn/utils/validation.py", line 2961, in validate_data
    X, y = check_X_y(X, y, **check_params)
  File "/Users/thiarakante/Documents/Databeez/prediction_parcours copie/.venv/lib/python3.10/site-packages/sklearn/utils/validation.py", line 1370, in check_X_y
    X = check_array(
  File "/Users/thiarakante/Documents/Databeez/prediction_parcours copie/.venv/lib/python3.10/site-packages/sklearn/utils/validation.py", line 1055, in check_array
    array = _asarray_with_order(array, order=order, dtype=dtype, xp=xp)
  File "/Users/thiarakante/Documents/Databeez/prediction_parcours copie/.venv/lib/python3.10/site-packages/sklearn/utils/_array_api.py", line 839, in _asarray_with_order
    array = numpy.asarray(array, order=order, dtype=dtype)
ValueError: could not convert string to float: 'S2'
Traceback (most recent call last):
  File "/Users/thiarakante/Documents/Databeez/prediction_parcours copie/main.py", line 41, in main
    pipeline, model, label_encoder, model_name = train_and_compare_models(df)
  File "/Users/thiarakante/Documents/Databeez/prediction_parcours copie/src/components/modelling.py", line 74, in train_and_compare_models
    cv_scores = cross_val_score(pipe, X, y_encoded, cv=4, scoring='accuracy')
  File "/Users/thiarakante/Documents/Databeez/prediction_parcours copie/.venv/lib/python3.10/site-packages/sklearn/utils/_param_validation.py", line 216, in wrapper
    return func(*args, **kwargs)
  File "/Users/thiarakante/Documents/Databeez/prediction_parcours copie/.venv/lib/python3.10/site-packages/sklearn/model_selection/_validation.py", line 684, in cross_val_score
    cv_results = cross_validate(
  File "/Users/thiarakante/Documents/Databeez/prediction_parcours copie/.venv/lib/python3.10/site-packages/sklearn/utils/_param_validation.py", line 216, in wrapper
    return func(*args, **kwargs)
  File "/Users/thiarakante/Documents/Databeez/prediction_parcours copie/.venv/lib/python3.10/site-packages/sklearn/model_selection/_validation.py", line 431, in cross_validate
    _warn_or_raise_about_fit_failures(results, error_score)
  File "/Users/thiarakante/Documents/Databeez/prediction_parcours copie/.venv/lib/python3.10/site-packages/sklearn/model_selection/_validation.py", line 517, in _warn_or_raise_about_fit_failures
    raise ValueError(all_fits_failed_message)
ValueError: 
All the 4 fits failed.
It is very likely that your model is misconfigured.
You can try to debug the error by setting error_score='raise'.

Below are more details about the failures:
--------------------------------------------------------------------------------
1 fits failed with the following error:
Traceback (most recent call last):
  File "/Users/thiarakante/Documents/Databeez/prediction_parcours copie/.venv/lib/python3.10/site-packages/sklearn/model_selection/_validation.py", line 866, in _fit_and_score
    estimator.fit(X_train, y_train, **fit_params)
  File "/Users/thiarakante/Documents/Databeez/prediction_parcours copie/.venv/lib/python3.10/site-packages/sklearn/base.py", line 1389, in wrapper
    return fit_method(estimator, *args, **kwargs)
  File "/Users/thiarakante/Documents/Databeez/prediction_parcours copie/.venv/lib/python3.10/site-packages/sklearn/pipeline.py", line 662, in fit
    self._final_estimator.fit(Xt, y, **last_step_params["fit"])
  File "/Users/thiarakante/Documents/Databeez/prediction_parcours copie/.venv/lib/python3.10/site-packages/sklearn/base.py", line 1389, in wrapper
    return fit_method(estimator, *args, **kwargs)
  File "/Users/thiarakante/Documents/Databeez/prediction_parcours copie/.venv/lib/python3.10/site-packages/sklearn/linear_model/_logistic.py", line 1222, in fit
    X, y = validate_data(
  File "/Users/thiarakante/Documents/Databeez/prediction_parcours copie/.venv/lib/python3.10/site-packages/sklearn/utils/validation.py", line 2961, in validate_data
    X, y = check_X_y(X, y, **check_params)
  File "/Users/thiarakante/Documents/Databeez/prediction_parcours copie/.venv/lib/python3.10/site-packages/sklearn/utils/validation.py", line 1370, in check_X_y
    X = check_array(
  File "/Users/thiarakante/Documents/Databeez/prediction_parcours copie/.venv/lib/python3.10/site-packages/sklearn/utils/validation.py", line 1055, in check_array
    array = _asarray_with_order(array, order=order, dtype=dtype, xp=xp)
  File "/Users/thiarakante/Documents/Databeez/prediction_parcours copie/.venv/lib/python3.10/site-packages/sklearn/utils/_array_api.py", line 839, in _asarray_with_order
    array = numpy.asarray(array, order=order, dtype=dtype)
ValueError: could not convert string to float: 'S4'

--------------------------------------------------------------------------------
3 fits failed with the following error:
Traceback (most recent call last):
  File "/Users/thiarakante/Documents/Databeez/prediction_parcours copie/.venv/lib/python3.10/site-packages/sklearn/model_selection/_validation.py", line 866, in _fit_and_score
    estimator.fit(X_train, y_train, **fit_params)
  File "/Users/thiarakante/Documents/Databeez/prediction_parcours copie/.venv/lib/python3.10/site-packages/sklearn/base.py", line 1389, in wrapper
    return fit_method(estimator, *args, **kwargs)
  File "/Users/thiarakante/Documents/Databeez/prediction_parcours copie/.venv/lib/python3.10/site-packages/sklearn/pipeline.py", line 662, in fit
    self._final_estimator.fit(Xt, y, **last_step_params["fit"])
  File "/Users/thiarakante/Documents/Databeez/prediction_parcours copie/.venv/lib/python3.10/site-packages/sklearn/base.py", line 1389, in wrapper
    return fit_method(estimator, *args, **kwargs)
  File "/Users/thiarakante/Documents/Databeez/prediction_parcours copie/.venv/lib/python3.10/site-packages/sklearn/linear_model/_logistic.py", line 1222, in fit
    X, y = validate_data(
  File "/Users/thiarakante/Documents/Databeez/prediction_parcours copie/.venv/lib/python3.10/site-packages/sklearn/utils/validation.py", line 2961, in validate_data
    X, y = check_X_y(X, y, **check_params)
  File "/Users/thiarakante/Documents/Databeez/prediction_parcours copie/.venv/lib/python3.10/site-packages/sklearn/utils/validation.py", line 1370, in check_X_y
    X = check_array(
  File "/Users/thiarakante/Documents/Databeez/prediction_parcours copie/.venv/lib/python3.10/site-packages/sklearn/utils/validation.py", line 1055, in check_array
    array = _asarray_with_order(array, order=order, dtype=dtype, xp=xp)
  File "/Users/thiarakante/Documents/Databeez/prediction_parcours copie/.venv/lib/python3.10/site-packages/sklearn/utils/_array_api.py", line 839, in _asarray_with_order
    array = numpy.asarray(array, order=order, dtype=dtype)
ValueError: could not convert string to float: 'S2'

2025-06-19 12:54:52,488 - INFO - Chargement des données depuis /Users/thiarakante/Documents/Databeez/prediction_parcours/src/data/shift_data.xlsx
2025-06-19 12:54:52,647 - INFO - Données chargées : 402 lignes, 13 colonnes
2025-06-19 12:54:52,648 - INFO - Colonnes disponibles : ['numero etudiant', 'Sciences_fondamentales', 'Biologie_Biophysique', 'Electronique_Automatique', 'Mécanique', 'Communication', 'Semestre', 'Maintenance_Systèmes', 'Gestion_Risques_HQSE', 'Informatique', 'Biomédical', 'Moyenne_generale', 'decision_semestrielle']
2025-06-19 12:54:52,648 - INFO - Valeurs cibles uniques : ['valide' 'Non valide']
2025-06-19 12:54:52,648 - INFO - Début de l'entraînement des modèles...
2025-06-19 12:54:52,661 - ERROR - Erreur lors de l'exécution : 
All the 4 fits failed.
It is very likely that your model is misconfigured.
You can try to debug the error by setting error_score='raise'.

Below are more details about the failures:
--------------------------------------------------------------------------------
1 fits failed with the following error:
Traceback (most recent call last):
  File "/Users/thiarakante/Documents/Databeez/prediction_parcours copie/.venv/lib/python3.10/site-packages/sklearn/model_selection/_validation.py", line 866, in _fit_and_score
    estimator.fit(X_train, y_train, **fit_params)
  File "/Users/thiarakante/Documents/Databeez/prediction_parcours copie/.venv/lib/python3.10/site-packages/sklearn/base.py", line 1389, in wrapper
    return fit_method(estimator, *args, **kwargs)
  File "/Users/thiarakante/Documents/Databeez/prediction_parcours copie/.venv/lib/python3.10/site-packages/sklearn/pipeline.py", line 662, in fit
    self._final_estimator.fit(Xt, y, **last_step_params["fit"])
  File "/Users/thiarakante/Documents/Databeez/prediction_parcours copie/.venv/lib/python3.10/site-packages/sklearn/base.py", line 1389, in wrapper
    return fit_method(estimator, *args, **kwargs)
  File "/Users/thiarakante/Documents/Databeez/prediction_parcours copie/.venv/lib/python3.10/site-packages/sklearn/linear_model/_logistic.py", line 1222, in fit
    X, y = validate_data(
  File "/Users/thiarakante/Documents/Databeez/prediction_parcours copie/.venv/lib/python3.10/site-packages/sklearn/utils/validation.py", line 2961, in validate_data
    X, y = check_X_y(X, y, **check_params)
  File "/Users/thiarakante/Documents/Databeez/prediction_parcours copie/.venv/lib/python3.10/site-packages/sklearn/utils/validation.py", line 1370, in check_X_y
    X = check_array(
  File "/Users/thiarakante/Documents/Databeez/prediction_parcours copie/.venv/lib/python3.10/site-packages/sklearn/utils/validation.py", line 1055, in check_array
    array = _asarray_with_order(array, order=order, dtype=dtype, xp=xp)
  File "/Users/thiarakante/Documents/Databeez/prediction_parcours copie/.venv/lib/python3.10/site-packages/sklearn/utils/_array_api.py", line 839, in _asarray_with_order
    array = numpy.asarray(array, order=order, dtype=dtype)
ValueError: could not convert string to float: 'S4'

--------------------------------------------------------------------------------
3 fits failed with the following error:
Traceback (most recent call last):
  File "/Users/thiarakante/Documents/Databeez/prediction_parcours copie/.venv/lib/python3.10/site-packages/sklearn/model_selection/_validation.py", line 866, in _fit_and_score
    estimator.fit(X_train, y_train, **fit_params)
  File "/Users/thiarakante/Documents/Databeez/prediction_parcours copie/.venv/lib/python3.10/site-packages/sklearn/base.py", line 1389, in wrapper
    return fit_method(estimator, *args, **kwargs)
  File "/Users/thiarakante/Documents/Databeez/prediction_parcours copie/.venv/lib/python3.10/site-packages/sklearn/pipeline.py", line 662, in fit
    self._final_estimator.fit(Xt, y, **last_step_params["fit"])
  File "/Users/thiarakante/Documents/Databeez/prediction_parcours copie/.venv/lib/python3.10/site-packages/sklearn/base.py", line 1389, in wrapper
    return fit_method(estimator, *args, **kwargs)
  File "/Users/thiarakante/Documents/Databeez/prediction_parcours copie/.venv/lib/python3.10/site-packages/sklearn/linear_model/_logistic.py", line 1222, in fit
    X, y = validate_data(
  File "/Users/thiarakante/Documents/Databeez/prediction_parcours copie/.venv/lib/python3.10/site-packages/sklearn/utils/validation.py", line 2961, in validate_data
    X, y = check_X_y(X, y, **check_params)
  File "/Users/thiarakante/Documents/Databeez/prediction_parcours copie/.venv/lib/python3.10/site-packages/sklearn/utils/validation.py", line 1370, in check_X_y
    X = check_array(
  File "/Users/thiarakante/Documents/Databeez/prediction_parcours copie/.venv/lib/python3.10/site-packages/sklearn/utils/validation.py", line 1055, in check_array
    array = _asarray_with_order(array, order=order, dtype=dtype, xp=xp)
  File "/Users/thiarakante/Documents/Databeez/prediction_parcours copie/.venv/lib/python3.10/site-packages/sklearn/utils/_array_api.py", line 839, in _asarray_with_order
    array = numpy.asarray(array, order=order, dtype=dtype)
ValueError: could not convert string to float: 'S2'
Traceback (most recent call last):
  File "/Users/thiarakante/Documents/Databeez/prediction_parcours copie/main.py", line 41, in main
    pipeline, model, label_encoder, model_name = train_and_compare_models(df)
  File "/Users/thiarakante/Documents/Databeez/prediction_parcours copie/src/components/modelling.py", line 74, in train_and_compare_models
    cv_scores = cross_val_score(pipe, X, y_encoded, cv=4, scoring='accuracy')
  File "/Users/thiarakante/Documents/Databeez/prediction_parcours copie/.venv/lib/python3.10/site-packages/sklearn/utils/_param_validation.py", line 216, in wrapper
    return func(*args, **kwargs)
  File "/Users/thiarakante/Documents/Databeez/prediction_parcours copie/.venv/lib/python3.10/site-packages/sklearn/model_selection/_validation.py", line 684, in cross_val_score
    cv_results = cross_validate(
  File "/Users/thiarakante/Documents/Databeez/prediction_parcours copie/.venv/lib/python3.10/site-packages/sklearn/utils/_param_validation.py", line 216, in wrapper
    return func(*args, **kwargs)
  File "/Users/thiarakante/Documents/Databeez/prediction_parcours copie/.venv/lib/python3.10/site-packages/sklearn/model_selection/_validation.py", line 431, in cross_validate
    _warn_or_raise_about_fit_failures(results, error_score)
  File "/Users/thiarakante/Documents/Databeez/prediction_parcours copie/.venv/lib/python3.10/site-packages/sklearn/model_selection/_validation.py", line 517, in _warn_or_raise_about_fit_failures
    raise ValueError(all_fits_failed_message)
ValueError: 
All the 4 fits failed.
It is very likely that your model is misconfigured.
You can try to debug the error by setting error_score='raise'.

Below are more details about the failures:
--------------------------------------------------------------------------------
1 fits failed with the following error:
Traceback (most recent call last):
  File "/Users/thiarakante/Documents/Databeez/prediction_parcours copie/.venv/lib/python3.10/site-packages/sklearn/model_selection/_validation.py", line 866, in _fit_and_score
    estimator.fit(X_train, y_train, **fit_params)
  File "/Users/thiarakante/Documents/Databeez/prediction_parcours copie/.venv/lib/python3.10/site-packages/sklearn/base.py", line 1389, in wrapper
    return fit_method(estimator, *args, **kwargs)
  File "/Users/thiarakante/Documents/Databeez/prediction_parcours copie/.venv/lib/python3.10/site-packages/sklearn/pipeline.py", line 662, in fit
    self._final_estimator.fit(Xt, y, **last_step_params["fit"])
  File "/Users/thiarakante/Documents/Databeez/prediction_parcours copie/.venv/lib/python3.10/site-packages/sklearn/base.py", line 1389, in wrapper
    return fit_method(estimator, *args, **kwargs)
  File "/Users/thiarakante/Documents/Databeez/prediction_parcours copie/.venv/lib/python3.10/site-packages/sklearn/linear_model/_logistic.py", line 1222, in fit
    X, y = validate_data(
  File "/Users/thiarakante/Documents/Databeez/prediction_parcours copie/.venv/lib/python3.10/site-packages/sklearn/utils/validation.py", line 2961, in validate_data
    X, y = check_X_y(X, y, **check_params)
  File "/Users/thiarakante/Documents/Databeez/prediction_parcours copie/.venv/lib/python3.10/site-packages/sklearn/utils/validation.py", line 1370, in check_X_y
    X = check_array(
  File "/Users/thiarakante/Documents/Databeez/prediction_parcours copie/.venv/lib/python3.10/site-packages/sklearn/utils/validation.py", line 1055, in check_array
    array = _asarray_with_order(array, order=order, dtype=dtype, xp=xp)
  File "/Users/thiarakante/Documents/Databeez/prediction_parcours copie/.venv/lib/python3.10/site-packages/sklearn/utils/_array_api.py", line 839, in _asarray_with_order
    array = numpy.asarray(array, order=order, dtype=dtype)
ValueError: could not convert string to float: 'S4'

--------------------------------------------------------------------------------
3 fits failed with the following error:
Traceback (most recent call last):
  File "/Users/thiarakante/Documents/Databeez/prediction_parcours copie/.venv/lib/python3.10/site-packages/sklearn/model_selection/_validation.py", line 866, in _fit_and_score
    estimator.fit(X_train, y_train, **fit_params)
  File "/Users/thiarakante/Documents/Databeez/prediction_parcours copie/.venv/lib/python3.10/site-packages/sklearn/base.py", line 1389, in wrapper
    return fit_method(estimator, *args, **kwargs)
  File "/Users/thiarakante/Documents/Databeez/prediction_parcours copie/.venv/lib/python3.10/site-packages/sklearn/pipeline.py", line 662, in fit
    self._final_estimator.fit(Xt, y, **last_step_params["fit"])
  File "/Users/thiarakante/Documents/Databeez/prediction_parcours copie/.venv/lib/python3.10/site-packages/sklearn/base.py", line 1389, in wrapper
    return fit_method(estimator, *args, **kwargs)
  File "/Users/thiarakante/Documents/Databeez/prediction_parcours copie/.venv/lib/python3.10/site-packages/sklearn/linear_model/_logistic.py", line 1222, in fit
    X, y = validate_data(
  File "/Users/thiarakante/Documents/Databeez/prediction_parcours copie/.venv/lib/python3.10/site-packages/sklearn/utils/validation.py", line 2961, in validate_data
    X, y = check_X_y(X, y, **check_params)
  File "/Users/thiarakante/Documents/Databeez/prediction_parcours copie/.venv/lib/python3.10/site-packages/sklearn/utils/validation.py", line 1370, in check_X_y
    X = check_array(
  File "/Users/thiarakante/Documents/Databeez/prediction_parcours copie/.venv/lib/python3.10/site-packages/sklearn/utils/validation.py", line 1055, in check_array
    array = _asarray_with_order(array, order=order, dtype=dtype, xp=xp)
  File "/Users/thiarakante/Documents/Databeez/prediction_parcours copie/.venv/lib/python3.10/site-packages/sklearn/utils/_array_api.py", line 839, in _asarray_with_order
    array = numpy.asarray(array, order=order, dtype=dtype)
ValueError: could not convert string to float: 'S2'

2025-06-19 13:00:37,075 - INFO - Chargement des données depuis /Users/thiarakante/Documents/Databeez/prediction_parcours/src/data/shift_data.xlsx
2025-06-19 13:00:37,200 - INFO - Données chargées : 402 lignes, 13 colonnes
2025-06-19 13:00:37,200 - INFO - Colonnes disponibles : ['numero etudiant', 'Sciences_fondamentales', 'Biologie_Biophysique', 'Electronique_Automatique', 'Mécanique', 'Communication', 'Semestre', 'Maintenance_Systèmes', 'Gestion_Risques_HQSE', 'Informatique', 'Biomédical', 'Moyenne_generale', 'decision_semestrielle']
2025-06-19 13:00:37,201 - INFO - Valeurs cibles uniques : ['valide' 'Non valide']
2025-06-19 13:00:37,201 - INFO - Début de l'entraînement des modèles...
2025-06-19 13:00:37,215 - ERROR - Erreur lors de l'exécution : 
All the 4 fits failed.
It is very likely that your model is misconfigured.
You can try to debug the error by setting error_score='raise'.

Below are more details about the failures:
--------------------------------------------------------------------------------
1 fits failed with the following error:
Traceback (most recent call last):
  File "/Users/thiarakante/Documents/Databeez/prediction_parcours copie/.venv/lib/python3.10/site-packages/sklearn/model_selection/_validation.py", line 866, in _fit_and_score
    estimator.fit(X_train, y_train, **fit_params)
  File "/Users/thiarakante/Documents/Databeez/prediction_parcours copie/.venv/lib/python3.10/site-packages/sklearn/base.py", line 1389, in wrapper
    return fit_method(estimator, *args, **kwargs)
  File "/Users/thiarakante/Documents/Databeez/prediction_parcours copie/.venv/lib/python3.10/site-packages/sklearn/pipeline.py", line 662, in fit
    self._final_estimator.fit(Xt, y, **last_step_params["fit"])
  File "/Users/thiarakante/Documents/Databeez/prediction_parcours copie/.venv/lib/python3.10/site-packages/sklearn/base.py", line 1389, in wrapper
    return fit_method(estimator, *args, **kwargs)
  File "/Users/thiarakante/Documents/Databeez/prediction_parcours copie/.venv/lib/python3.10/site-packages/sklearn/linear_model/_logistic.py", line 1222, in fit
    X, y = validate_data(
  File "/Users/thiarakante/Documents/Databeez/prediction_parcours copie/.venv/lib/python3.10/site-packages/sklearn/utils/validation.py", line 2961, in validate_data
    X, y = check_X_y(X, y, **check_params)
  File "/Users/thiarakante/Documents/Databeez/prediction_parcours copie/.venv/lib/python3.10/site-packages/sklearn/utils/validation.py", line 1370, in check_X_y
    X = check_array(
  File "/Users/thiarakante/Documents/Databeez/prediction_parcours copie/.venv/lib/python3.10/site-packages/sklearn/utils/validation.py", line 1055, in check_array
    array = _asarray_with_order(array, order=order, dtype=dtype, xp=xp)
  File "/Users/thiarakante/Documents/Databeez/prediction_parcours copie/.venv/lib/python3.10/site-packages/sklearn/utils/_array_api.py", line 839, in _asarray_with_order
    array = numpy.asarray(array, order=order, dtype=dtype)
ValueError: could not convert string to float: 'S4'

--------------------------------------------------------------------------------
3 fits failed with the following error:
Traceback (most recent call last):
  File "/Users/thiarakante/Documents/Databeez/prediction_parcours copie/.venv/lib/python3.10/site-packages/sklearn/model_selection/_validation.py", line 866, in _fit_and_score
    estimator.fit(X_train, y_train, **fit_params)
  File "/Users/thiarakante/Documents/Databeez/prediction_parcours copie/.venv/lib/python3.10/site-packages/sklearn/base.py", line 1389, in wrapper
    return fit_method(estimator, *args, **kwargs)
  File "/Users/thiarakante/Documents/Databeez/prediction_parcours copie/.venv/lib/python3.10/site-packages/sklearn/pipeline.py", line 662, in fit
    self._final_estimator.fit(Xt, y, **last_step_params["fit"])
  File "/Users/thiarakante/Documents/Databeez/prediction_parcours copie/.venv/lib/python3.10/site-packages/sklearn/base.py", line 1389, in wrapper
    return fit_method(estimator, *args, **kwargs)
  File "/Users/thiarakante/Documents/Databeez/prediction_parcours copie/.venv/lib/python3.10/site-packages/sklearn/linear_model/_logistic.py", line 1222, in fit
    X, y = validate_data(
  File "/Users/thiarakante/Documents/Databeez/prediction_parcours copie/.venv/lib/python3.10/site-packages/sklearn/utils/validation.py", line 2961, in validate_data
    X, y = check_X_y(X, y, **check_params)
  File "/Users/thiarakante/Documents/Databeez/prediction_parcours copie/.venv/lib/python3.10/site-packages/sklearn/utils/validation.py", line 1370, in check_X_y
    X = check_array(
  File "/Users/thiarakante/Documents/Databeez/prediction_parcours copie/.venv/lib/python3.10/site-packages/sklearn/utils/validation.py", line 1055, in check_array
    array = _asarray_with_order(array, order=order, dtype=dtype, xp=xp)
  File "/Users/thiarakante/Documents/Databeez/prediction_parcours copie/.venv/lib/python3.10/site-packages/sklearn/utils/_array_api.py", line 839, in _asarray_with_order
    array = numpy.asarray(array, order=order, dtype=dtype)
ValueError: could not convert string to float: 'S2'
Traceback (most recent call last):
  File "/Users/thiarakante/Documents/Databeez/prediction_parcours copie/main.py", line 41, in main
    pipeline, model, label_encoder, model_name = train_and_compare_models(df)
  File "/Users/thiarakante/Documents/Databeez/prediction_parcours copie/src/components/modelling.py", line 74, in train_and_compare_models
    cv_scores = cross_val_score(pipe, X, y_encoded, cv=4, scoring='accuracy')
  File "/Users/thiarakante/Documents/Databeez/prediction_parcours copie/.venv/lib/python3.10/site-packages/sklearn/utils/_param_validation.py", line 216, in wrapper
    return func(*args, **kwargs)
  File "/Users/thiarakante/Documents/Databeez/prediction_parcours copie/.venv/lib/python3.10/site-packages/sklearn/model_selection/_validation.py", line 684, in cross_val_score
    cv_results = cross_validate(
  File "/Users/thiarakante/Documents/Databeez/prediction_parcours copie/.venv/lib/python3.10/site-packages/sklearn/utils/_param_validation.py", line 216, in wrapper
    return func(*args, **kwargs)
  File "/Users/thiarakante/Documents/Databeez/prediction_parcours copie/.venv/lib/python3.10/site-packages/sklearn/model_selection/_validation.py", line 431, in cross_validate
    _warn_or_raise_about_fit_failures(results, error_score)
  File "/Users/thiarakante/Documents/Databeez/prediction_parcours copie/.venv/lib/python3.10/site-packages/sklearn/model_selection/_validation.py", line 517, in _warn_or_raise_about_fit_failures
    raise ValueError(all_fits_failed_message)
ValueError: 
All the 4 fits failed.
It is very likely that your model is misconfigured.
You can try to debug the error by setting error_score='raise'.

Below are more details about the failures:
--------------------------------------------------------------------------------
1 fits failed with the following error:
Traceback (most recent call last):
  File "/Users/thiarakante/Documents/Databeez/prediction_parcours copie/.venv/lib/python3.10/site-packages/sklearn/model_selection/_validation.py", line 866, in _fit_and_score
    estimator.fit(X_train, y_train, **fit_params)
  File "/Users/thiarakante/Documents/Databeez/prediction_parcours copie/.venv/lib/python3.10/site-packages/sklearn/base.py", line 1389, in wrapper
    return fit_method(estimator, *args, **kwargs)
  File "/Users/thiarakante/Documents/Databeez/prediction_parcours copie/.venv/lib/python3.10/site-packages/sklearn/pipeline.py", line 662, in fit
    self._final_estimator.fit(Xt, y, **last_step_params["fit"])
  File "/Users/thiarakante/Documents/Databeez/prediction_parcours copie/.venv/lib/python3.10/site-packages/sklearn/base.py", line 1389, in wrapper
    return fit_method(estimator, *args, **kwargs)
  File "/Users/thiarakante/Documents/Databeez/prediction_parcours copie/.venv/lib/python3.10/site-packages/sklearn/linear_model/_logistic.py", line 1222, in fit
    X, y = validate_data(
  File "/Users/thiarakante/Documents/Databeez/prediction_parcours copie/.venv/lib/python3.10/site-packages/sklearn/utils/validation.py", line 2961, in validate_data
    X, y = check_X_y(X, y, **check_params)
  File "/Users/thiarakante/Documents/Databeez/prediction_parcours copie/.venv/lib/python3.10/site-packages/sklearn/utils/validation.py", line 1370, in check_X_y
    X = check_array(
  File "/Users/thiarakante/Documents/Databeez/prediction_parcours copie/.venv/lib/python3.10/site-packages/sklearn/utils/validation.py", line 1055, in check_array
    array = _asarray_with_order(array, order=order, dtype=dtype, xp=xp)
  File "/Users/thiarakante/Documents/Databeez/prediction_parcours copie/.venv/lib/python3.10/site-packages/sklearn/utils/_array_api.py", line 839, in _asarray_with_order
    array = numpy.asarray(array, order=order, dtype=dtype)
ValueError: could not convert string to float: 'S4'

--------------------------------------------------------------------------------
3 fits failed with the following error:
Traceback (most recent call last):
  File "/Users/thiarakante/Documents/Databeez/prediction_parcours copie/.venv/lib/python3.10/site-packages/sklearn/model_selection/_validation.py", line 866, in _fit_and_score
    estimator.fit(X_train, y_train, **fit_params)
  File "/Users/thiarakante/Documents/Databeez/prediction_parcours copie/.venv/lib/python3.10/site-packages/sklearn/base.py", line 1389, in wrapper
    return fit_method(estimator, *args, **kwargs)
  File "/Users/thiarakante/Documents/Databeez/prediction_parcours copie/.venv/lib/python3.10/site-packages/sklearn/pipeline.py", line 662, in fit
    self._final_estimator.fit(Xt, y, **last_step_params["fit"])
  File "/Users/thiarakante/Documents/Databeez/prediction_parcours copie/.venv/lib/python3.10/site-packages/sklearn/base.py", line 1389, in wrapper
    return fit_method(estimator, *args, **kwargs)
  File "/Users/thiarakante/Documents/Databeez/prediction_parcours copie/.venv/lib/python3.10/site-packages/sklearn/linear_model/_logistic.py", line 1222, in fit
    X, y = validate_data(
  File "/Users/thiarakante/Documents/Databeez/prediction_parcours copie/.venv/lib/python3.10/site-packages/sklearn/utils/validation.py", line 2961, in validate_data
    X, y = check_X_y(X, y, **check_params)
  File "/Users/thiarakante/Documents/Databeez/prediction_parcours copie/.venv/lib/python3.10/site-packages/sklearn/utils/validation.py", line 1370, in check_X_y
    X = check_array(
  File "/Users/thiarakante/Documents/Databeez/prediction_parcours copie/.venv/lib/python3.10/site-packages/sklearn/utils/validation.py", line 1055, in check_array
    array = _asarray_with_order(array, order=order, dtype=dtype, xp=xp)
  File "/Users/thiarakante/Documents/Databeez/prediction_parcours copie/.venv/lib/python3.10/site-packages/sklearn/utils/_array_api.py", line 839, in _asarray_with_order
    array = numpy.asarray(array, order=order, dtype=dtype)
ValueError: could not convert string to float: 'S2'

2025-06-19 13:02:09,723 - INFO - Chargement des données depuis /Users/thiarakante/Documents/Databeez/prediction_parcours/src/data/shift_data.xlsx
2025-06-19 13:02:09,835 - INFO - Données chargées : 402 lignes, 13 colonnes
2025-06-19 13:02:09,835 - INFO - Colonnes disponibles : ['numero etudiant', 'Sciences_fondamentales', 'Biologie_Biophysique', 'Electronique_Automatique', 'Mécanique', 'Communication', 'Semestre', 'Maintenance_Systèmes', 'Gestion_Risques_HQSE', 'Informatique', 'Biomédical', 'Moyenne_generale', 'decision_semestrielle']
2025-06-19 13:02:09,836 - INFO - Valeurs cibles uniques : ['valide' 'Non valide']
2025-06-19 13:02:09,836 - INFO - Début de l'entraînement des modèles...
2025-06-19 13:02:09,852 - ERROR - Erreur lors de l'exécution : 
All the 4 fits failed.
It is very likely that your model is misconfigured.
You can try to debug the error by setting error_score='raise'.

Below are more details about the failures:
--------------------------------------------------------------------------------
1 fits failed with the following error:
Traceback (most recent call last):
  File "/Users/thiarakante/Documents/Databeez/prediction_parcours copie/.venv/lib/python3.10/site-packages/sklearn/model_selection/_validation.py", line 866, in _fit_and_score
    estimator.fit(X_train, y_train, **fit_params)
  File "/Users/thiarakante/Documents/Databeez/prediction_parcours copie/.venv/lib/python3.10/site-packages/sklearn/base.py", line 1389, in wrapper
    return fit_method(estimator, *args, **kwargs)
  File "/Users/thiarakante/Documents/Databeez/prediction_parcours copie/.venv/lib/python3.10/site-packages/sklearn/pipeline.py", line 662, in fit
    self._final_estimator.fit(Xt, y, **last_step_params["fit"])
  File "/Users/thiarakante/Documents/Databeez/prediction_parcours copie/.venv/lib/python3.10/site-packages/sklearn/base.py", line 1389, in wrapper
    return fit_method(estimator, *args, **kwargs)
  File "/Users/thiarakante/Documents/Databeez/prediction_parcours copie/.venv/lib/python3.10/site-packages/sklearn/linear_model/_logistic.py", line 1222, in fit
    X, y = validate_data(
  File "/Users/thiarakante/Documents/Databeez/prediction_parcours copie/.venv/lib/python3.10/site-packages/sklearn/utils/validation.py", line 2961, in validate_data
    X, y = check_X_y(X, y, **check_params)
  File "/Users/thiarakante/Documents/Databeez/prediction_parcours copie/.venv/lib/python3.10/site-packages/sklearn/utils/validation.py", line 1370, in check_X_y
    X = check_array(
  File "/Users/thiarakante/Documents/Databeez/prediction_parcours copie/.venv/lib/python3.10/site-packages/sklearn/utils/validation.py", line 1055, in check_array
    array = _asarray_with_order(array, order=order, dtype=dtype, xp=xp)
  File "/Users/thiarakante/Documents/Databeez/prediction_parcours copie/.venv/lib/python3.10/site-packages/sklearn/utils/_array_api.py", line 839, in _asarray_with_order
    array = numpy.asarray(array, order=order, dtype=dtype)
ValueError: could not convert string to float: 'S4'

--------------------------------------------------------------------------------
3 fits failed with the following error:
Traceback (most recent call last):
  File "/Users/thiarakante/Documents/Databeez/prediction_parcours copie/.venv/lib/python3.10/site-packages/sklearn/model_selection/_validation.py", line 866, in _fit_and_score
    estimator.fit(X_train, y_train, **fit_params)
  File "/Users/thiarakante/Documents/Databeez/prediction_parcours copie/.venv/lib/python3.10/site-packages/sklearn/base.py", line 1389, in wrapper
    return fit_method(estimator, *args, **kwargs)
  File "/Users/thiarakante/Documents/Databeez/prediction_parcours copie/.venv/lib/python3.10/site-packages/sklearn/pipeline.py", line 662, in fit
    self._final_estimator.fit(Xt, y, **last_step_params["fit"])
  File "/Users/thiarakante/Documents/Databeez/prediction_parcours copie/.venv/lib/python3.10/site-packages/sklearn/base.py", line 1389, in wrapper
    return fit_method(estimator, *args, **kwargs)
  File "/Users/thiarakante/Documents/Databeez/prediction_parcours copie/.venv/lib/python3.10/site-packages/sklearn/linear_model/_logistic.py", line 1222, in fit
    X, y = validate_data(
  File "/Users/thiarakante/Documents/Databeez/prediction_parcours copie/.venv/lib/python3.10/site-packages/sklearn/utils/validation.py", line 2961, in validate_data
    X, y = check_X_y(X, y, **check_params)
  File "/Users/thiarakante/Documents/Databeez/prediction_parcours copie/.venv/lib/python3.10/site-packages/sklearn/utils/validation.py", line 1370, in check_X_y
    X = check_array(
  File "/Users/thiarakante/Documents/Databeez/prediction_parcours copie/.venv/lib/python3.10/site-packages/sklearn/utils/validation.py", line 1055, in check_array
    array = _asarray_with_order(array, order=order, dtype=dtype, xp=xp)
  File "/Users/thiarakante/Documents/Databeez/prediction_parcours copie/.venv/lib/python3.10/site-packages/sklearn/utils/_array_api.py", line 839, in _asarray_with_order
    array = numpy.asarray(array, order=order, dtype=dtype)
ValueError: could not convert string to float: 'S2'
Traceback (most recent call last):
  File "/Users/thiarakante/Documents/Databeez/prediction_parcours copie/main.py", line 41, in main
    pipeline, model, label_encoder, model_name = train_and_compare_models(df)
  File "/Users/thiarakante/Documents/Databeez/prediction_parcours copie/src/components/modelling.py", line 74, in train_and_compare_models
    cv_scores = cross_val_score(pipe, X, y_encoded, cv=4, scoring='accuracy')
  File "/Users/thiarakante/Documents/Databeez/prediction_parcours copie/.venv/lib/python3.10/site-packages/sklearn/utils/_param_validation.py", line 216, in wrapper
    return func(*args, **kwargs)
  File "/Users/thiarakante/Documents/Databeez/prediction_parcours copie/.venv/lib/python3.10/site-packages/sklearn/model_selection/_validation.py", line 684, in cross_val_score
    cv_results = cross_validate(
  File "/Users/thiarakante/Documents/Databeez/prediction_parcours copie/.venv/lib/python3.10/site-packages/sklearn/utils/_param_validation.py", line 216, in wrapper
    return func(*args, **kwargs)
  File "/Users/thiarakante/Documents/Databeez/prediction_parcours copie/.venv/lib/python3.10/site-packages/sklearn/model_selection/_validation.py", line 431, in cross_validate
    _warn_or_raise_about_fit_failures(results, error_score)
  File "/Users/thiarakante/Documents/Databeez/prediction_parcours copie/.venv/lib/python3.10/site-packages/sklearn/model_selection/_validation.py", line 517, in _warn_or_raise_about_fit_failures
    raise ValueError(all_fits_failed_message)
ValueError: 
All the 4 fits failed.
It is very likely that your model is misconfigured.
You can try to debug the error by setting error_score='raise'.

Below are more details about the failures:
--------------------------------------------------------------------------------
1 fits failed with the following error:
Traceback (most recent call last):
  File "/Users/thiarakante/Documents/Databeez/prediction_parcours copie/.venv/lib/python3.10/site-packages/sklearn/model_selection/_validation.py", line 866, in _fit_and_score
    estimator.fit(X_train, y_train, **fit_params)
  File "/Users/thiarakante/Documents/Databeez/prediction_parcours copie/.venv/lib/python3.10/site-packages/sklearn/base.py", line 1389, in wrapper
    return fit_method(estimator, *args, **kwargs)
  File "/Users/thiarakante/Documents/Databeez/prediction_parcours copie/.venv/lib/python3.10/site-packages/sklearn/pipeline.py", line 662, in fit
    self._final_estimator.fit(Xt, y, **last_step_params["fit"])
  File "/Users/thiarakante/Documents/Databeez/prediction_parcours copie/.venv/lib/python3.10/site-packages/sklearn/base.py", line 1389, in wrapper
    return fit_method(estimator, *args, **kwargs)
  File "/Users/thiarakante/Documents/Databeez/prediction_parcours copie/.venv/lib/python3.10/site-packages/sklearn/linear_model/_logistic.py", line 1222, in fit
    X, y = validate_data(
  File "/Users/thiarakante/Documents/Databeez/prediction_parcours copie/.venv/lib/python3.10/site-packages/sklearn/utils/validation.py", line 2961, in validate_data
    X, y = check_X_y(X, y, **check_params)
  File "/Users/thiarakante/Documents/Databeez/prediction_parcours copie/.venv/lib/python3.10/site-packages/sklearn/utils/validation.py", line 1370, in check_X_y
    X = check_array(
  File "/Users/thiarakante/Documents/Databeez/prediction_parcours copie/.venv/lib/python3.10/site-packages/sklearn/utils/validation.py", line 1055, in check_array
    array = _asarray_with_order(array, order=order, dtype=dtype, xp=xp)
  File "/Users/thiarakante/Documents/Databeez/prediction_parcours copie/.venv/lib/python3.10/site-packages/sklearn/utils/_array_api.py", line 839, in _asarray_with_order
    array = numpy.asarray(array, order=order, dtype=dtype)
ValueError: could not convert string to float: 'S4'

--------------------------------------------------------------------------------
3 fits failed with the following error:
Traceback (most recent call last):
  File "/Users/thiarakante/Documents/Databeez/prediction_parcours copie/.venv/lib/python3.10/site-packages/sklearn/model_selection/_validation.py", line 866, in _fit_and_score
    estimator.fit(X_train, y_train, **fit_params)
  File "/Users/thiarakante/Documents/Databeez/prediction_parcours copie/.venv/lib/python3.10/site-packages/sklearn/base.py", line 1389, in wrapper
    return fit_method(estimator, *args, **kwargs)
  File "/Users/thiarakante/Documents/Databeez/prediction_parcours copie/.venv/lib/python3.10/site-packages/sklearn/pipeline.py", line 662, in fit
    self._final_estimator.fit(Xt, y, **last_step_params["fit"])
  File "/Users/thiarakante/Documents/Databeez/prediction_parcours copie/.venv/lib/python3.10/site-packages/sklearn/base.py", line 1389, in wrapper
    return fit_method(estimator, *args, **kwargs)
  File "/Users/thiarakante/Documents/Databeez/prediction_parcours copie/.venv/lib/python3.10/site-packages/sklearn/linear_model/_logistic.py", line 1222, in fit
    X, y = validate_data(
  File "/Users/thiarakante/Documents/Databeez/prediction_parcours copie/.venv/lib/python3.10/site-packages/sklearn/utils/validation.py", line 2961, in validate_data
    X, y = check_X_y(X, y, **check_params)
  File "/Users/thiarakante/Documents/Databeez/prediction_parcours copie/.venv/lib/python3.10/site-packages/sklearn/utils/validation.py", line 1370, in check_X_y
    X = check_array(
  File "/Users/thiarakante/Documents/Databeez/prediction_parcours copie/.venv/lib/python3.10/site-packages/sklearn/utils/validation.py", line 1055, in check_array
    array = _asarray_with_order(array, order=order, dtype=dtype, xp=xp)
  File "/Users/thiarakante/Documents/Databeez/prediction_parcours copie/.venv/lib/python3.10/site-packages/sklearn/utils/_array_api.py", line 839, in _asarray_with_order
    array = numpy.asarray(array, order=order, dtype=dtype)
ValueError: could not convert string to float: 'S2'

2025-06-19 13:02:38,938 - INFO - Chargement des données depuis /Users/thiarakante/Documents/Databeez/prediction_parcours/src/data/shift_data.xlsx
2025-06-19 13:02:39,110 - INFO - Données chargées : 402 lignes, 13 colonnes
2025-06-19 13:02:39,110 - INFO - Colonnes disponibles : ['numero etudiant', 'Sciences_fondamentales', 'Biologie_Biophysique', 'Electronique_Automatique', 'Mécanique', 'Communication', 'Semestre', 'Maintenance_Systèmes', 'Gestion_Risques_HQSE', 'Informatique', 'Biomédical', 'Moyenne_generale', 'decision_semestrielle']
2025-06-19 13:02:39,112 - INFO - Valeurs cibles uniques : ['valide' 'Non valide']
2025-06-19 13:02:39,112 - INFO - Début de l'entraînement des modèles...
2025-06-19 13:02:39,146 - ERROR - Erreur lors de l'exécution : 
All the 4 fits failed.
It is very likely that your model is misconfigured.
You can try to debug the error by setting error_score='raise'.

Below are more details about the failures:
--------------------------------------------------------------------------------
1 fits failed with the following error:
Traceback (most recent call last):
  File "/Users/thiarakante/Documents/Databeez/prediction_parcours copie/.venv/lib/python3.10/site-packages/sklearn/model_selection/_validation.py", line 866, in _fit_and_score
    estimator.fit(X_train, y_train, **fit_params)
  File "/Users/thiarakante/Documents/Databeez/prediction_parcours copie/.venv/lib/python3.10/site-packages/sklearn/base.py", line 1389, in wrapper
    return fit_method(estimator, *args, **kwargs)
  File "/Users/thiarakante/Documents/Databeez/prediction_parcours copie/.venv/lib/python3.10/site-packages/sklearn/pipeline.py", line 662, in fit
    self._final_estimator.fit(Xt, y, **last_step_params["fit"])
  File "/Users/thiarakante/Documents/Databeez/prediction_parcours copie/.venv/lib/python3.10/site-packages/sklearn/base.py", line 1389, in wrapper
    return fit_method(estimator, *args, **kwargs)
  File "/Users/thiarakante/Documents/Databeez/prediction_parcours copie/.venv/lib/python3.10/site-packages/sklearn/linear_model/_logistic.py", line 1222, in fit
    X, y = validate_data(
  File "/Users/thiarakante/Documents/Databeez/prediction_parcours copie/.venv/lib/python3.10/site-packages/sklearn/utils/validation.py", line 2961, in validate_data
    X, y = check_X_y(X, y, **check_params)
  File "/Users/thiarakante/Documents/Databeez/prediction_parcours copie/.venv/lib/python3.10/site-packages/sklearn/utils/validation.py", line 1370, in check_X_y
    X = check_array(
  File "/Users/thiarakante/Documents/Databeez/prediction_parcours copie/.venv/lib/python3.10/site-packages/sklearn/utils/validation.py", line 1055, in check_array
    array = _asarray_with_order(array, order=order, dtype=dtype, xp=xp)
  File "/Users/thiarakante/Documents/Databeez/prediction_parcours copie/.venv/lib/python3.10/site-packages/sklearn/utils/_array_api.py", line 839, in _asarray_with_order
    array = numpy.asarray(array, order=order, dtype=dtype)
ValueError: could not convert string to float: 'S4'

--------------------------------------------------------------------------------
3 fits failed with the following error:
Traceback (most recent call last):
  File "/Users/thiarakante/Documents/Databeez/prediction_parcours copie/.venv/lib/python3.10/site-packages/sklearn/model_selection/_validation.py", line 866, in _fit_and_score
    estimator.fit(X_train, y_train, **fit_params)
  File "/Users/thiarakante/Documents/Databeez/prediction_parcours copie/.venv/lib/python3.10/site-packages/sklearn/base.py", line 1389, in wrapper
    return fit_method(estimator, *args, **kwargs)
  File "/Users/thiarakante/Documents/Databeez/prediction_parcours copie/.venv/lib/python3.10/site-packages/sklearn/pipeline.py", line 662, in fit
    self._final_estimator.fit(Xt, y, **last_step_params["fit"])
  File "/Users/thiarakante/Documents/Databeez/prediction_parcours copie/.venv/lib/python3.10/site-packages/sklearn/base.py", line 1389, in wrapper
    return fit_method(estimator, *args, **kwargs)
  File "/Users/thiarakante/Documents/Databeez/prediction_parcours copie/.venv/lib/python3.10/site-packages/sklearn/linear_model/_logistic.py", line 1222, in fit
    X, y = validate_data(
  File "/Users/thiarakante/Documents/Databeez/prediction_parcours copie/.venv/lib/python3.10/site-packages/sklearn/utils/validation.py", line 2961, in validate_data
    X, y = check_X_y(X, y, **check_params)
  File "/Users/thiarakante/Documents/Databeez/prediction_parcours copie/.venv/lib/python3.10/site-packages/sklearn/utils/validation.py", line 1370, in check_X_y
    X = check_array(
  File "/Users/thiarakante/Documents/Databeez/prediction_parcours copie/.venv/lib/python3.10/site-packages/sklearn/utils/validation.py", line 1055, in check_array
    array = _asarray_with_order(array, order=order, dtype=dtype, xp=xp)
  File "/Users/thiarakante/Documents/Databeez/prediction_parcours copie/.venv/lib/python3.10/site-packages/sklearn/utils/_array_api.py", line 839, in _asarray_with_order
    array = numpy.asarray(array, order=order, dtype=dtype)
ValueError: could not convert string to float: 'S2'
Traceback (most recent call last):
  File "/Users/thiarakante/Documents/Databeez/prediction_parcours copie/main.py", line 41, in main
    pipeline, model, label_encoder, model_name = train_and_compare_models(df)
  File "/Users/thiarakante/Documents/Databeez/prediction_parcours copie/src/components/modelling.py", line 74, in train_and_compare_models
    cv_scores = cross_val_score(pipe, X, y_encoded, cv=4, scoring='accuracy')
  File "/Users/thiarakante/Documents/Databeez/prediction_parcours copie/.venv/lib/python3.10/site-packages/sklearn/utils/_param_validation.py", line 216, in wrapper
    return func(*args, **kwargs)
  File "/Users/thiarakante/Documents/Databeez/prediction_parcours copie/.venv/lib/python3.10/site-packages/sklearn/model_selection/_validation.py", line 684, in cross_val_score
    cv_results = cross_validate(
  File "/Users/thiarakante/Documents/Databeez/prediction_parcours copie/.venv/lib/python3.10/site-packages/sklearn/utils/_param_validation.py", line 216, in wrapper
    return func(*args, **kwargs)
  File "/Users/thiarakante/Documents/Databeez/prediction_parcours copie/.venv/lib/python3.10/site-packages/sklearn/model_selection/_validation.py", line 431, in cross_validate
    _warn_or_raise_about_fit_failures(results, error_score)
  File "/Users/thiarakante/Documents/Databeez/prediction_parcours copie/.venv/lib/python3.10/site-packages/sklearn/model_selection/_validation.py", line 517, in _warn_or_raise_about_fit_failures
    raise ValueError(all_fits_failed_message)
ValueError: 
All the 4 fits failed.
It is very likely that your model is misconfigured.
You can try to debug the error by setting error_score='raise'.

Below are more details about the failures:
--------------------------------------------------------------------------------
1 fits failed with the following error:
Traceback (most recent call last):
  File "/Users/thiarakante/Documents/Databeez/prediction_parcours copie/.venv/lib/python3.10/site-packages/sklearn/model_selection/_validation.py", line 866, in _fit_and_score
    estimator.fit(X_train, y_train, **fit_params)
  File "/Users/thiarakante/Documents/Databeez/prediction_parcours copie/.venv/lib/python3.10/site-packages/sklearn/base.py", line 1389, in wrapper
    return fit_method(estimator, *args, **kwargs)
  File "/Users/thiarakante/Documents/Databeez/prediction_parcours copie/.venv/lib/python3.10/site-packages/sklearn/pipeline.py", line 662, in fit
    self._final_estimator.fit(Xt, y, **last_step_params["fit"])
  File "/Users/thiarakante/Documents/Databeez/prediction_parcours copie/.venv/lib/python3.10/site-packages/sklearn/base.py", line 1389, in wrapper
    return fit_method(estimator, *args, **kwargs)
  File "/Users/thiarakante/Documents/Databeez/prediction_parcours copie/.venv/lib/python3.10/site-packages/sklearn/linear_model/_logistic.py", line 1222, in fit
    X, y = validate_data(
  File "/Users/thiarakante/Documents/Databeez/prediction_parcours copie/.venv/lib/python3.10/site-packages/sklearn/utils/validation.py", line 2961, in validate_data
    X, y = check_X_y(X, y, **check_params)
  File "/Users/thiarakante/Documents/Databeez/prediction_parcours copie/.venv/lib/python3.10/site-packages/sklearn/utils/validation.py", line 1370, in check_X_y
    X = check_array(
  File "/Users/thiarakante/Documents/Databeez/prediction_parcours copie/.venv/lib/python3.10/site-packages/sklearn/utils/validation.py", line 1055, in check_array
    array = _asarray_with_order(array, order=order, dtype=dtype, xp=xp)
  File "/Users/thiarakante/Documents/Databeez/prediction_parcours copie/.venv/lib/python3.10/site-packages/sklearn/utils/_array_api.py", line 839, in _asarray_with_order
    array = numpy.asarray(array, order=order, dtype=dtype)
ValueError: could not convert string to float: 'S4'

--------------------------------------------------------------------------------
3 fits failed with the following error:
Traceback (most recent call last):
  File "/Users/thiarakante/Documents/Databeez/prediction_parcours copie/.venv/lib/python3.10/site-packages/sklearn/model_selection/_validation.py", line 866, in _fit_and_score
    estimator.fit(X_train, y_train, **fit_params)
  File "/Users/thiarakante/Documents/Databeez/prediction_parcours copie/.venv/lib/python3.10/site-packages/sklearn/base.py", line 1389, in wrapper
    return fit_method(estimator, *args, **kwargs)
  File "/Users/thiarakante/Documents/Databeez/prediction_parcours copie/.venv/lib/python3.10/site-packages/sklearn/pipeline.py", line 662, in fit
    self._final_estimator.fit(Xt, y, **last_step_params["fit"])
  File "/Users/thiarakante/Documents/Databeez/prediction_parcours copie/.venv/lib/python3.10/site-packages/sklearn/base.py", line 1389, in wrapper
    return fit_method(estimator, *args, **kwargs)
  File "/Users/thiarakante/Documents/Databeez/prediction_parcours copie/.venv/lib/python3.10/site-packages/sklearn/linear_model/_logistic.py", line 1222, in fit
    X, y = validate_data(
  File "/Users/thiarakante/Documents/Databeez/prediction_parcours copie/.venv/lib/python3.10/site-packages/sklearn/utils/validation.py", line 2961, in validate_data
    X, y = check_X_y(X, y, **check_params)
  File "/Users/thiarakante/Documents/Databeez/prediction_parcours copie/.venv/lib/python3.10/site-packages/sklearn/utils/validation.py", line 1370, in check_X_y
    X = check_array(
  File "/Users/thiarakante/Documents/Databeez/prediction_parcours copie/.venv/lib/python3.10/site-packages/sklearn/utils/validation.py", line 1055, in check_array
    array = _asarray_with_order(array, order=order, dtype=dtype, xp=xp)
  File "/Users/thiarakante/Documents/Databeez/prediction_parcours copie/.venv/lib/python3.10/site-packages/sklearn/utils/_array_api.py", line 839, in _asarray_with_order
    array = numpy.asarray(array, order=order, dtype=dtype)
ValueError: could not convert string to float: 'S2'

2025-06-19 13:07:29,146 - INFO - Chargement des données depuis /Users/thiarakante/Documents/Databeez/prediction_parcours/src/data/shift_data.xlsx
2025-06-19 13:07:29,281 - INFO - Données chargées : 402 lignes, 13 colonnes
2025-06-19 13:07:29,281 - INFO - Colonnes disponibles : ['numero etudiant', 'Sciences_fondamentales', 'Biologie_Biophysique', 'Electronique_Automatique', 'Mécanique', 'Communication', 'Semestre', 'Maintenance_Systèmes', 'Gestion_Risques_HQSE', 'Informatique', 'Biomédical', 'Moyenne_generale', 'decision_semestrielle']
2025-06-19 13:07:29,282 - INFO - Valeurs cibles uniques : ['valide' 'Non valide']
2025-06-19 13:07:29,282 - INFO - Début de l'entraînement des modèles...
2025-06-19 13:07:29,307 - ERROR - Erreur lors de l'exécution : ''
Traceback (most recent call last):
  File "/Users/thiarakante/Documents/Databeez/prediction_parcours copie/main.py", line 41, in main
    pipeline, model, label_encoder, model_name = train_and_compare_models(df)
  File "/Users/thiarakante/Documents/Databeez/prediction_parcours copie/src/components/modelling.py", line 83, in train_and_compare_models
    return best_model, base_models[best_name], label_encoder, best_name
KeyError: ''
2025-06-19 13:11:15,338 - INFO - Chargement des données depuis /Users/thiarakante/Documents/Databeez/prediction_parcours/src/data/shift_data.xlsx
2025-06-19 13:11:15,459 - INFO - Données chargées : 402 lignes, 13 colonnes
2025-06-19 13:11:15,459 - INFO - Colonnes disponibles : ['numero etudiant', 'Sciences_fondamentales', 'Biologie_Biophysique', 'Electronique_Automatique', 'Mécanique', 'Communication', 'Semestre', 'Maintenance_Systèmes', 'Gestion_Risques_HQSE', 'Informatique', 'Biomédical', 'Moyenne_generale', 'decision_semestrielle']
2025-06-19 13:11:15,460 - INFO - Valeurs cibles uniques : ['valide' 'Non valide']
2025-06-19 13:11:15,460 - INFO - Début de l'entraînement des modèles...
2025-06-19 13:11:15,583 - INFO - Entraînement terminé en 0.12 secondes
2025-06-19 13:11:15,583 - INFO - Meilleur modèle sélectionné : RandomForest
2025-06-19 13:11:15,584 - INFO - Sauvegarde des artefacts...
2025-06-19 13:11:15,603 - ERROR - Erreur lors de l'exécution : 'preprocessing'
Traceback (most recent call last):
  File "/Users/thiarakante/Documents/Databeez/prediction_parcours copie/main.py", line 49, in main
    save_artifacts(pipeline, label_encoder, name=model_name)
  File "/Users/thiarakante/Documents/Databeez/prediction_parcours copie/src/components/modelling.py", line 93, in save_artifacts
    preprocessor = pipeline.named_steps['preprocessing']
  File "/Users/thiarakante/Documents/Databeez/prediction_parcours copie/.venv/lib/python3.10/site-packages/sklearn/utils/_bunch.py", line 42, in __getitem__
    return super().__getitem__(key)
KeyError: 'preprocessing'
2025-06-19 13:16:12,868 - INFO - Chargement des données depuis /Users/thiarakante/Documents/Databeez/prediction_parcours/src/data/shift_data.xlsx
2025-06-19 13:16:12,977 - INFO - Données chargées : 402 lignes, 13 colonnes
2025-06-19 13:16:12,977 - INFO - Colonnes disponibles : ['numero etudiant', 'Sciences_fondamentales', 'Biologie_Biophysique', 'Electronique_Automatique', 'Mécanique', 'Communication', 'Semestre', 'Maintenance_Systèmes', 'Gestion_Risques_HQSE', 'Informatique', 'Biomédical', 'Moyenne_generale', 'decision_semestrielle']
2025-06-19 13:16:12,977 - INFO - Valeurs cibles uniques : ['valide' 'Non valide']
2025-06-19 13:16:12,977 - INFO - Début de l'entraînement des modèles...
2025-06-19 13:16:13,089 - INFO - Entraînement terminé en 0.11 secondes
2025-06-19 13:16:13,089 - INFO - Meilleur modèle sélectionné : RandomForest
2025-06-19 13:16:13,089 - INFO - Sauvegarde des artefacts...
2025-06-19 13:16:13,125 - INFO - Analyse des features importantes...
2025-06-19 13:16:13,125 - ERROR - Erreur lors de l'exécution : 'preprocessing'
Traceback (most recent call last):
  File "/Users/thiarakante/Documents/Databeez/prediction_parcours copie/main.py", line 54, in main
    feature_importances = show_feature_importance(pipeline, X)
  File "/Users/thiarakante/Documents/Databeez/prediction_parcours copie/src/components/modelling.py", line 115, in show_feature_importance
    preprocessor = pipeline.named_steps["preprocessing"]
  File "/Users/thiarakante/Documents/Databeez/prediction_parcours copie/.venv/lib/python3.10/site-packages/sklearn/utils/_bunch.py", line 42, in __getitem__
    return super().__getitem__(key)
KeyError: 'preprocessing'
2025-06-19 13:19:17,119 - INFO - Chargement des données depuis /Users/thiarakante/Documents/Databeez/prediction_parcours/src/data/shift_data.xlsx
2025-06-19 13:19:17,229 - INFO - Données chargées : 402 lignes, 13 colonnes
2025-06-19 13:19:17,230 - INFO - Colonnes disponibles : ['numero etudiant', 'Sciences_fondamentales', 'Biologie_Biophysique', 'Electronique_Automatique', 'Mécanique', 'Communication', 'Semestre', 'Maintenance_Systèmes', 'Gestion_Risques_HQSE', 'Informatique', 'Biomédical', 'Moyenne_generale', 'decision_semestrielle']
2025-06-19 13:19:17,230 - INFO - Valeurs cibles uniques : ['valide' 'Non valide']
2025-06-19 13:19:17,230 - INFO - Début de l'entraînement des modèles...
2025-06-19 13:19:17,341 - INFO - Entraînement terminé en 0.11 secondes
2025-06-19 13:19:17,341 - INFO - Meilleur modèle sélectionné : RandomForest
2025-06-19 13:19:17,341 - INFO - Sauvegarde des artefacts...
2025-06-19 13:19:17,378 - INFO - Analyse des features importantes...
2025-06-19 13:19:17,385 - INFO - Importances des features sauvegardées dans /Users/thiarakante/Documents/Databeez/prediction_parcours/src/components/artifacts/feature_importances.csv
2025-06-19 13:19:17,385 - INFO - Pipeline exécuté avec succès !
2025-06-19 13:25:36,223 - INFO - Chargement des données depuis /Users/thiarakante/Documents/Databeez/prediction_parcours/src/data/shift_data.xlsx
2025-06-19 13:25:36,327 - INFO - Données chargées : 402 lignes, 13 colonnes
2025-06-19 13:25:36,327 - INFO - Colonnes disponibles : ['numero etudiant', 'Sciences_fondamentales', 'Biologie_Biophysique', 'Electronique_Automatique', 'Mécanique', 'Communication', 'Semestre', 'Maintenance_Systèmes', 'Gestion_Risques_HQSE', 'Informatique', 'Biomédical', 'Moyenne_generale', 'decision_semestrielle']
2025-06-19 13:25:36,328 - INFO - Valeurs cibles uniques : ['valide' 'Non valide']
2025-06-19 13:25:36,328 - INFO - Début de l'entraînement des modèles...
2025-06-19 13:25:36,330 - ERROR - Erreur lors de l'exécution : ''
Traceback (most recent call last):
  File "/Users/thiarakante/Documents/Databeez/prediction_parcours copie/main.py", line 41, in main
    pipeline, model, label_encoder, model_name = train_and_compare_models(df)
  File "/Users/thiarakante/Documents/Databeez/prediction_parcours copie/src/components/modelling.py", line 83, in train_and_compare_models
    return best_model, base_models[best_name], label_encoder, best_name
KeyError: ''
2025-06-19 13:28:42,636 - INFO - Chargement des données depuis /Users/thiarakante/Documents/Databeez/prediction_parcours/src/data/shift_data.xlsx
2025-06-19 13:28:42,774 - INFO - Données chargées : 402 lignes, 13 colonnes
2025-06-19 13:28:42,774 - INFO - Colonnes disponibles : ['numero etudiant', 'Sciences_fondamentales', 'Biologie_Biophysique', 'Electronique_Automatique', 'Mécanique', 'Communication', 'Semestre', 'Maintenance_Systèmes', 'Gestion_Risques_HQSE', 'Informatique', 'Biomédical', 'Moyenne_generale', 'decision_semestrielle']
2025-06-19 13:28:42,775 - INFO - Valeurs cibles uniques : ['valide' 'Non valide']
2025-06-19 13:28:42,776 - INFO - Début de l'entraînement des modèles...
2025-06-19 13:28:42,780 - ERROR - Erreur lors de l'exécution : ''
Traceback (most recent call last):
  File "/Users/thiarakante/Documents/Databeez/prediction_parcours copie/main.py", line 41, in main
    pipeline, model, label_encoder, model_name = train_and_compare_models(df)
  File "/Users/thiarakante/Documents/Databeez/prediction_parcours copie/src/components/modelling.py", line 83, in train_and_compare_models
    return best_model, base_models[best_name], label_encoder, best_name
KeyError: ''
2025-06-19 13:29:26,428 - INFO - Chargement des données depuis /Users/thiarakante/Documents/Databeez/prediction_parcours/src/data/shift_data.xlsx
2025-06-19 13:29:26,542 - INFO - Données chargées : 402 lignes, 13 colonnes
2025-06-19 13:29:26,543 - INFO - Colonnes disponibles : ['numero etudiant', 'Sciences_fondamentales', 'Biologie_Biophysique', 'Electronique_Automatique', 'Mécanique', 'Communication', 'Semestre', 'Maintenance_Systèmes', 'Gestion_Risques_HQSE', 'Informatique', 'Biomédical', 'Moyenne_generale', 'decision_semestrielle']
2025-06-19 13:29:26,544 - INFO - Valeurs cibles uniques : ['valide' 'Non valide']
2025-06-19 13:29:26,544 - INFO - Début de l'entraînement des modèles...
2025-06-19 13:29:26,551 - ERROR - Erreur lors de l'exécution : ''
Traceback (most recent call last):
  File "/Users/thiarakante/Documents/Databeez/prediction_parcours copie/main.py", line 41, in main
    pipeline, model, label_encoder, model_name = train_and_compare_models(df)
  File "/Users/thiarakante/Documents/Databeez/prediction_parcours copie/src/components/modelling.py", line 83, in train_and_compare_models
    return best_model, base_models[best_name], label_encoder, best_name
KeyError: ''
2025-06-19 13:30:41,926 - INFO - Chargement des données depuis /Users/thiarakante/Documents/Databeez/prediction_parcours/src/data/shift_data.xlsx
2025-06-19 13:30:42,058 - INFO - Données chargées : 402 lignes, 13 colonnes
2025-06-19 13:30:42,058 - INFO - Colonnes disponibles : ['numero etudiant', 'Sciences_fondamentales', 'Biologie_Biophysique', 'Electronique_Automatique', 'Mécanique', 'Communication', 'Semestre', 'Maintenance_Systèmes', 'Gestion_Risques_HQSE', 'Informatique', 'Biomédical', 'Moyenne_generale', 'decision_semestrielle']
2025-06-19 13:30:42,058 - INFO - Valeurs cibles uniques : ['valide' 'Non valide']
2025-06-19 13:30:42,058 - INFO - Début de l'entraînement des modèles...
2025-06-19 13:30:42,062 - ERROR - Erreur lors de l'exécution : ''
Traceback (most recent call last):
  File "/Users/thiarakante/Documents/Databeez/prediction_parcours copie/main.py", line 41, in main
    pipeline, model, label_encoder, model_name = train_and_compare_models(df)
  File "/Users/thiarakante/Documents/Databeez/prediction_parcours copie/src/components/modelling.py", line 83, in train_and_compare_models
    return best_model, base_models[best_name], label_encoder, best_name
KeyError: ''
2025-06-19 13:31:13,275 - INFO - Chargement des données depuis /Users/thiarakante/Documents/Databeez/prediction_parcours/src/data/shift_data.xlsx
2025-06-19 13:31:13,385 - INFO - Données chargées : 402 lignes, 13 colonnes
2025-06-19 13:31:13,386 - INFO - Colonnes disponibles : ['numero etudiant', 'Sciences_fondamentales', 'Biologie_Biophysique', 'Electronique_Automatique', 'Mécanique', 'Communication', 'Semestre', 'Maintenance_Systèmes', 'Gestion_Risques_HQSE', 'Informatique', 'Biomédical', 'Moyenne_generale', 'decision_semestrielle']
2025-06-19 13:31:13,386 - INFO - Valeurs cibles uniques : ['valide' 'Non valide']
2025-06-19 13:31:13,386 - INFO - Début de l'entraînement des modèles...
2025-06-19 13:31:13,390 - ERROR - Erreur lors de l'exécution : ''
Traceback (most recent call last):
  File "/Users/thiarakante/Documents/Databeez/prediction_parcours copie/main.py", line 41, in main
    pipeline, model, label_encoder, model_name = train_and_compare_models(df)
  File "/Users/thiarakante/Documents/Databeez/prediction_parcours copie/src/components/modelling.py", line 83, in train_and_compare_models
    return best_model, base_models[best_name], label_encoder, best_name
KeyError: ''
2025-06-19 13:31:53,719 - INFO - Chargement des données depuis /Users/thiarakante/Documents/Databeez/prediction_parcours/src/data/shift_data.xlsx
2025-06-19 13:31:53,913 - INFO - Données chargées : 402 lignes, 13 colonnes
2025-06-19 13:31:53,913 - INFO - Colonnes disponibles : ['numero etudiant', 'Sciences_fondamentales', 'Biologie_Biophysique', 'Electronique_Automatique', 'Mécanique', 'Communication', 'Semestre', 'Maintenance_Systèmes', 'Gestion_Risques_HQSE', 'Informatique', 'Biomédical', 'Moyenne_generale', 'decision_semestrielle']
2025-06-19 13:31:53,915 - INFO - Valeurs cibles uniques : ['valide' 'Non valide']
2025-06-19 13:31:53,915 - INFO - Début de l'entraînement des modèles...
2025-06-19 13:31:54,136 - INFO - Entraînement terminé en 0.22 secondes
2025-06-19 13:31:54,137 - INFO - Meilleur modèle sélectionné : RandomForest
2025-06-19 13:31:54,137 - INFO - Sauvegarde des artefacts...
2025-06-19 13:31:54,204 - INFO - Analyse des features importantes...
2025-06-19 13:31:54,210 - INFO - Importances des features sauvegardées dans /Users/thiarakante/Documents/Databeez/prediction_parcours/src/components/artifacts/feature_importances.csv
2025-06-19 13:31:54,210 - INFO - Pipeline exécuté avec succès !
2025-06-19 13:44:40,237 - INFO - Chargement des données depuis /Users/thiarakante/Documents/Databeez/prediction_parcours/src/data/shift_data.xlsx
2025-06-19 13:44:40,356 - INFO - Données chargées : 402 lignes, 13 colonnes
2025-06-19 13:44:40,356 - INFO - Colonnes disponibles : ['numero etudiant', 'Sciences_fondamentales', 'Biologie_Biophysique', 'Electronique_Automatique', 'Mécanique', 'Communication', 'Semestre', 'Maintenance_Systèmes', 'Gestion_Risques_HQSE', 'Informatique', 'Biomédical', 'Moyenne_generale', 'decision_semestrielle']
2025-06-19 13:44:40,356 - INFO - Valeurs cibles uniques : ['valide' 'Non valide']
2025-06-19 13:44:40,356 - INFO - Début de l'entraînement des modèles...
2025-06-19 13:44:40,359 - ERROR - Erreur lors de l'exécution : ''
Traceback (most recent call last):
  File "/Users/thiarakante/Documents/Databeez/prediction_parcours copie/main.py", line 41, in main
    pipeline, model, label_encoder, model_name = train_and_compare_models(df)
  File "/Users/thiarakante/Documents/Databeez/prediction_parcours copie/src/components/modelling.py", line 87, in train_and_compare_models
    return best_model, base_models[best_name], label_encoder, best_name
KeyError: ''
2025-06-19 13:47:42,225 - INFO - Chargement des données depuis /Users/thiarakante/Documents/Databeez/prediction_parcours/src/data/shift_data.xlsx
2025-06-19 13:47:42,341 - INFO - Données chargées : 402 lignes, 13 colonnes
2025-06-19 13:47:42,341 - INFO - Colonnes disponibles : ['numero etudiant', 'Sciences_fondamentales', 'Biologie_Biophysique', 'Electronique_Automatique', 'Mécanique', 'Communication', 'Semestre', 'Maintenance_Systèmes', 'Gestion_Risques_HQSE', 'Informatique', 'Biomédical', 'Moyenne_generale', 'decision_semestrielle']
2025-06-19 13:47:42,341 - INFO - Valeurs cibles uniques : ['valide' 'Non valide']
2025-06-19 13:47:42,341 - INFO - Début de l'entraînement des modèles...
2025-06-19 13:47:42,474 - INFO - Entraînement terminé en 0.13 secondes
2025-06-19 13:47:42,474 - INFO - Meilleur modèle sélectionné : RandomForest
2025-06-19 13:47:42,474 - INFO - Sauvegarde des artefacts...
2025-06-19 13:47:42,509 - INFO - Analyse des features importantes...
2025-06-19 13:47:42,513 - INFO - Importances des features sauvegardées dans /Users/thiarakante/Documents/Databeez/prediction_parcours/src/components/artifacts/feature_importances.csv
2025-06-19 13:47:42,513 - INFO - Pipeline exécuté avec succès !
2025-06-19 13:52:09,601 - INFO - Chargement des données depuis /Users/thiarakante/Documents/Databeez/prediction_parcours/src/data/shift_data.xlsx
2025-06-19 13:52:09,745 - INFO - Données chargées : 402 lignes, 13 colonnes
2025-06-19 13:52:09,745 - INFO - Colonnes disponibles : ['numero etudiant', 'Sciences_fondamentales', 'Biologie_Biophysique', 'Electronique_Automatique', 'Mécanique', 'Communication', 'Semestre', 'Maintenance_Systèmes', 'Gestion_Risques_HQSE', 'Informatique', 'Biomédical', 'Moyenne_generale', 'decision_semestrielle']
2025-06-19 13:52:09,746 - INFO - Valeurs cibles uniques : ['valide' 'Non valide']
2025-06-19 13:52:09,746 - INFO - Début de l'entraînement des modèles...
2025-06-19 13:52:09,863 - INFO - Entraînement terminé en 0.12 secondes
2025-06-19 13:52:09,863 - INFO - Meilleur modèle sélectionné : RandomForest
2025-06-19 13:52:09,863 - INFO - Sauvegarde des artefacts...
2025-06-19 13:52:09,904 - INFO - Analyse des features importantes...
2025-06-19 13:52:09,909 - INFO - Importances des features sauvegardées dans /Users/thiarakante/Documents/Databeez/prediction_parcours/src/components/artifacts/feature_importances.csv
2025-06-19 13:52:09,909 - INFO - Pipeline exécuté avec succès !
2025-06-19 13:54:27,631 - INFO - Chargement depuis chemin/vers/vos/données.xlsx
2025-06-19 13:54:27,635 - ERROR - Échec du processus
Traceback (most recent call last):
  File "/Users/thiarakante/Documents/Databeez/prediction_parcours copie/main.py", line 40, in main
    df = pd.read_excel(data_path)
  File "/Users/thiarakante/Documents/Databeez/prediction_parcours copie/.venv/lib/python3.10/site-packages/pandas/io/excel/_base.py", line 495, in read_excel
    io = ExcelFile(
  File "/Users/thiarakante/Documents/Databeez/prediction_parcours copie/.venv/lib/python3.10/site-packages/pandas/io/excel/_base.py", line 1550, in __init__
    ext = inspect_excel_format(
  File "/Users/thiarakante/Documents/Databeez/prediction_parcours copie/.venv/lib/python3.10/site-packages/pandas/io/excel/_base.py", line 1402, in inspect_excel_format
    with get_handle(
  File "/Users/thiarakante/Documents/Databeez/prediction_parcours copie/.venv/lib/python3.10/site-packages/pandas/io/common.py", line 882, in get_handle
    handle = open(handle, ioargs.mode)
FileNotFoundError: [Errno 2] No such file or directory: 'chemin/vers/vos/données.xlsx'
2025-06-19 13:55:06,796 - INFO - Chargement depuis /Users/thiarakante/Documents/Databeez/prediction_parcours copie/src/data/shift_data.xlsx 
2025-06-19 13:55:06,800 - ERROR - Échec du processus
Traceback (most recent call last):
  File "/Users/thiarakante/Documents/Databeez/prediction_parcours copie/main.py", line 40, in main
    df = pd.read_excel(data_path)
  File "/Users/thiarakante/Documents/Databeez/prediction_parcours copie/.venv/lib/python3.10/site-packages/pandas/io/excel/_base.py", line 495, in read_excel
    io = ExcelFile(
  File "/Users/thiarakante/Documents/Databeez/prediction_parcours copie/.venv/lib/python3.10/site-packages/pandas/io/excel/_base.py", line 1550, in __init__
    ext = inspect_excel_format(
  File "/Users/thiarakante/Documents/Databeez/prediction_parcours copie/.venv/lib/python3.10/site-packages/pandas/io/excel/_base.py", line 1402, in inspect_excel_format
    with get_handle(
  File "/Users/thiarakante/Documents/Databeez/prediction_parcours copie/.venv/lib/python3.10/site-packages/pandas/io/common.py", line 882, in get_handle
    handle = open(handle, ioargs.mode)
FileNotFoundError: [Errno 2] No such file or directory: '/Users/thiarakante/Documents/Databeez/prediction_parcours copie/src/data/shift_data.xlsx '
2025-06-19 13:56:31,945 - INFO - Chargement des données depuis /Users/thiarakante/Documents/Databeez/prediction_parcours/src/data/shift_data.xlsx
2025-06-19 13:56:32,353 - INFO - Lancement de l'entraînement...
2025-06-19 13:56:32,558 - INFO - Temps d'entraînement: 0.19s
2025-06-19 13:56:32,558 - INFO - Modèle sélectionné: RandomForest
2025-06-19 13:56:32,606 - INFO - Processus terminé avec succès
2025-06-19 14:05:27,748 - INFO - Chargement des données depuis /Users/thiarakante/Documents/Databeez/prediction_parcours/src/data/shift_data.xlsx
2025-06-19 14:05:27,880 - INFO - Lancement de l'entraînement...
2025-06-19 14:05:28,007 - INFO - Temps d'entraînement: 0.13s
2025-06-19 14:05:28,007 - INFO - Modèle sélectionné: RandomForest
2025-06-19 14:05:28,049 - ERROR - Échec du processus
Traceback (most recent call last):
  File "/Users/thiarakante/Documents/Databeez/prediction_parcours copie/main.py", line 45, in main
    X = X.drop(columns=["decision_semestrielle"])
UnboundLocalError: local variable 'X' referenced before assignment
2025-06-19 14:14:10,910 - INFO - Chargement des données depuis /Users/thiarakante/Documents/Databeez/prediction_parcours/src/data/shift_data.xlsx
2025-06-19 14:14:11,024 - INFO - Lancement de l'entraînement...
2025-06-19 14:14:11,128 - INFO - Temps d'entraînement: 0.10s
2025-06-19 14:14:11,128 - INFO - Modèle sélectionné: RandomForest
2025-06-19 14:14:11,173 - INFO - Processus terminé avec succès
2025-06-19 14:41:21,640 - INFO - Chargement des données depuis /Users/thiarakante/Documents/Databeez/prediction_parcours/src/data/shift_data.xlsx
2025-06-19 14:41:21,749 - INFO - Lancement de l'entraînement...
2025-06-19 14:41:21,755 - ERROR - Échec du processus
Traceback (most recent call last):
  File "/Users/thiarakante/Documents/Databeez/prediction_parcours copie/main.py", line 36, in main
    pipeline, model, label_encoder, model_name = train_and_compare_models(df)
  File "/Users/thiarakante/Documents/Databeez/prediction_parcours copie/src/components/modelling.py", line 83, in train_and_compare_models
    return best_model, base_models[best_name], label_encoder, best_name
KeyError: ''
2025-06-19 15:10:50,928 - INFO - Chargement des données depuis /Users/thiarakante/Documents/Databeez/prediction_parcours/src/data/shift_data.xlsx
2025-06-19 15:10:51,285 - INFO - Lancement de l'entraînement...
2025-06-19 15:10:51,390 - INFO - Temps d'entraînement: 0.10s
2025-06-19 15:10:51,390 - INFO - Modèle sélectionné: RandomForest
2025-06-19 15:10:51,443 - INFO - Processus terminé avec succès
2025-06-19 15:13:39,162 - INFO - Chargement des données depuis /Users/thiarakante/Documents/Databeez/prediction_parcours/src/data/shift_data.xlsx
2025-06-19 15:13:39,348 - INFO - Lancement de l'entraînement...
2025-06-19 15:13:39,464 - INFO - Temps d'entraînement: 0.12s
2025-06-19 15:13:39,464 - INFO - Modèle sélectionné: RandomForest
2025-06-19 15:13:39,513 - INFO - Processus terminé avec succès
2025-06-19 15:14:24,866 - INFO - Chargement des données depuis /Users/thiarakante/Documents/Databeez/prediction_parcours/src/data/shift_data.xlsx
2025-06-19 15:14:25,008 - INFO - Lancement de l'entraînement...
2025-06-19 15:14:25,115 - INFO - Temps d'entraînement: 0.11s
2025-06-19 15:14:25,115 - INFO - Modèle sélectionné: RandomForest
2025-06-19 15:14:25,152 - INFO - Processus terminé avec succès
2025-06-19 15:15:36,183 - INFO - Chargement des données depuis /Users/thiarakante/Documents/Databeez/prediction_parcours/src/data/shift_data.xlsx
2025-06-19 15:15:36,301 - INFO - Lancement de l'entraînement...
2025-06-19 15:15:36,431 - INFO - Temps d'entraînement: 0.13s
2025-06-19 15:15:36,431 - INFO - Modèle sélectionné: RandomForest
2025-06-19 15:15:36,475 - INFO - Processus terminé avec succès
